<?xml version="1.0" ?>
<!-- =================================================================================== -->
<!-- |    This document was autogenerated by xacro from src/manipulator_description/xacro/Custom_dsr.urdf.xacro | -->
<!-- |    EDITING THIS FILE BY HAND IS NOT RECOMMENDED                                 | -->
<!-- =================================================================================== -->
<robot name="m0609">
    <material name="black">
        <color rgba="0.0 0.0 0.0 1.0" />
    </material>
    <material name="white">
        <color rgba="1.0 1.0 1.0 1.0" />
    </material>
    <material name="orange">
        <color rgba="1.0 0.4 0.0 1.0" />
    </material>
    <material name="dr_gray">
        <color rgba="0.490 0.490 0.486 1.0" />
    </material>
    <material name="dr_white">
        <color rgba="0.941 0.941 0.941 1.0" />
    </material>
    <link name="base_0">
        <inertial>
            <mass value="3.18" />
            <origin xyz="-2.8e-05   -0.006045    0.038403" />
            <inertia ixx="0.017789" ixy="-7.4356e-06" ixz="3.0378e-06" iyy="0.011135" iyz="-0.00029038" izz="0.020054" />
        </inertial>
        <visual>
            <origin rpy="0 0 0" xyz="0 0 0" />
            <geometry>
                <mesh filename="package://dsr_description/meshes/m0609_white/MF0609_0_0.dae" scale="0.001 0.001 0.001" />
            </geometry>
        </visual>
    </link>
    <!-- joint 1 -->
    <joint name="joint1" type="revolute">
        <parent link="base_0" />
        <child link="link1" />
        <origin rpy="0 0 0" xyz="0 0 0.1" />
        <axis xyz="0 0 1" />
        <limit effort="163" lower="-6.2832" upper="6.2832" velocity="2.618" />
        <dynamics friction="0" />
    </joint>
    <link name="link1">
        <inertial>
            <mass value="5.02" />
            <origin xyz="7.2e-05    0.036227   -0.003417" rpy="0 0 0" />
            <inertia ixx="0.026195" ixy="2.3904e-05" ixz="-1.3319e-05" iyy="0.016899" iyz="-0.00071987" izz="0.022944" />
        </inertial>
        <collision>
            <geometry>
                <cylinder length="0.2" radius="0.08" />
            </geometry>
        </collision>
        <visual>
            <origin rpy="0 0 0" xyz="0 0 0" />
            <geometry>
                <mesh filename="package://dsr_description/meshes/m0609_white/MF0609_1_0.dae" scale="0.001 0.001 0.001" />
            </geometry>
        </visual>
    </link>
    <!-- joint2 -->
    <joint name="joint2" type="revolute">
        <parent link="link1" />
        <child link="link2" />
        <origin rpy="0 -1.571 -1.571" xyz="0 0.0062 0" />
        <axis xyz="0 0 1" />
        <limit effort="163" lower="-6.2832" upper="6.2832" velocity="2.618" />
        <dynamics friction="0" />
    </joint>
    <link name="link2">
        <inertial>
            <mass value="8.04" />
            <origin xyz="0.20447     2.6e-05     0.16005" rpy="0 0 0" />
            <inertia ixx="0.026743" ixy="-0.00019461" ixz="-0.00058734" iyy="0.30084" iyz="-6.7892e-06" izz="0.29898" />
        </inertial>
        <collision>
            <origin rpy="0 -1.571 0" xyz="0.2 0 0.1525" />
            <geometry>
                <cylinder length="0.5" radius="0.08" />
            </geometry>
        </collision>
        <visual>
            <origin rpy="0 0 0" xyz="0 0 0" />
            <geometry>
                <mesh filename="package://dsr_description/meshes/m0609_white/MF0609_2_0.dae" scale="0.001 0.001 0.001" />
            </geometry>
        </visual>
        <visual>
            <origin rpy="0 0 0" xyz="0 0 0" />
            <geometry>
                <mesh filename="package://dsr_description/meshes/m0609_white/MF0609_2_1.dae" scale="0.001 0.001 0.001" />
            </geometry>
        </visual>
        <visual>
            <origin rpy="0 0 0" xyz="0 0 0" />
            <geometry>
                <mesh filename="package://dsr_description/meshes/m0609_white/MF0609_2_2.dae" scale="0.001 0.001 0.001" />
            </geometry>
        </visual>
    </link>
    <!-- joint3 -->
    <joint name="joint3" type="revolute">
        <parent link="link2" />
        <child link="link3" />
        <origin rpy="0 0 1.571" xyz="0.411 0 0" />
        <axis xyz="0 0 1" />
        <limit effort="96" lower="-2.618" upper="2.618" velocity="3.1416" />
        <dynamics friction="0" />
    </joint>
    <link name="link3">
        <inertial>
            <mass value="3.6" />
            <origin xyz="-2.2e-05   -0.006867    0.043445" />
            <inertia ixx="0.018342" ixy="1.1302e-05" ixz="-4.5308e-06" iyy="0.018239" iyz="-0.00099247" izz="0.01326" />
        </inertial>
        <visual>
            <origin rpy="0 0 0" xyz="0 0 0" />
            <geometry>
                <mesh filename="package://dsr_description/meshes/m0609_white/MF0609_3_0.dae" scale="0.001 0.001 0.001" />
            </geometry>
        </visual>
    </link>
    <!-- joint4 -->
    <joint name="joint4" type="revolute">
        <parent link="link3" />
        <child link="link4" />
        <origin rpy="1.571 0 0" xyz="0 -0.368 0" />
        <axis xyz="0 0 1" />
        <limit effort="50" lower="-6.2832" upper="6.2832" velocity="3.927" />
        <dynamics friction="0" />
    </joint>
    <link name="link4">
        <inertial>
            <mass value="3.57" />
            <origin xyz="4e-05    0.097079    -0.10981" rpy="0 0 0" />
            <inertia ixx="0.08035" ixy="-4.6119e-06" ixz="-8.1798e-06" iyy="0.066005" iyz="-0.028996" izz="0.029763" />
        </inertial>
        <collision>
            <origin rpy="-0.55 0 0" xyz="0 0.075 -0.16" />
            <geometry>
                <cylinder length="0.4" radius="0.05" />
            </geometry>
        </collision>
        <visual>
            <origin rpy="0 0 0" xyz="0 0 0" />
            <geometry>
                <mesh filename="package://dsr_description/meshes/m0609_white/MF0609_4_0.dae" scale="0.001 0.001 0.001" />
            </geometry>
        </visual>
        <visual>
            <origin rpy="0 0 0" xyz="0 0 0" />
            <geometry>
                <mesh filename="package://dsr_description/meshes/m0609_white/MF0609_4_1.dae" scale="0.001 0.001 0.001" />
            </geometry>
        </visual>
    </link>
    <!-- joint5 -->
    <joint name="joint5" type="revolute">
        <parent link="link4" />
        <child link="link5" />
        <origin rpy="-1.571 0 0" xyz="0 0 0" />
        <axis xyz="0 0 1" />
        <limit effort="50" lower="-6.2832" upper="6.2832" velocity="3.927" />
        <dynamics friction="0" />
    </joint>
    <link name="link5">
        <inertial>
            <mass value="2.83" />
            <origin xyz="-6.8e-05    0.003827    0.031969" rpy="0 0 0" />
            <inertia ixx="0.014275" ixy="2.2026e-05" ixz="3.3017e-06" iyy="0.012569" iyz="0.00045077" izz="0.0085318" />
        </inertial>
        <collision>
            <origin rpy="1.571 0 0" xyz="0 0 0" />
            <geometry>
                <cylinder length="0.15" radius="0.06" />
            </geometry>
        </collision>
        <visual>
            <origin rpy="0 0 0" xyz="0 0 0" />
            <geometry>
                <mesh filename="package://dsr_description/meshes/m0609_white/MF0609_5_0.dae" scale="0.001 0.001 0.001" />
            </geometry>
        </visual>
    </link>
    <!-- joint6 -->
    <joint name="joint6" type="revolute">
        <parent link="link5" />
        <child link="link6" />
        <origin rpy="1.571 0 0" xyz="0 -0.121 0" />
        <axis xyz="0 0 1" />
        <limit effort="50" lower="-6.2832" upper="6.2832" velocity="3.927" />
        <dynamics friction="0" />
    </joint>
    <link name="link6">
        <inertial>
            <mass value="1.16" />
            <origin xyz="-3e-05    -4.5e-05     -0.0539" />
            <inertia ixx="0.0080226" ixy="1.371e-06" ixz="6.3578e-06" iyy="0.0053992" iyz="7.4676e-06" izz="0.0053912" />
        </inertial>
        <visual>
            <origin rpy="0 0 0" xyz="0 0 0" />
            <geometry>
                <mesh filename="package://dsr_description/meshes/m0609_white/MF0609_6_0.dae" scale="0.001 0.001 0.001" />
            </geometry>
        </visual>
    </link>
    <!-- Transmission 1 -->
    <transmission name="tran1">
        <type>transmission_interface/SimpleTransmission</type>
        <joint name="joint1">
            <hardwareInterface>hardware_interface/PositionJointInterface</hardwareInterface>
        </joint>
        <actuator name="motor1">
            <hardwareInterface>hardware_interface/PositionJointInterface</hardwareInterface>
            <mechanicalReduction>1</mechanicalReduction>
        </actuator>
    </transmission>
    <!-- Transmission 2 -->
    <transmission name="tran2">
        <type>transmission_interface/SimpleTransmission</type>
        <joint name="joint2">
            <hardwareInterface>hardware_interface/PositionJointInterface</hardwareInterface>
        </joint>
        <actuator name="motor2">
            <hardwareInterface>hardware_interface/PositionJointInterface</hardwareInterface>
            <mechanicalReduction>1</mechanicalReduction>
        </actuator>
    </transmission>
    <!-- Transmission 3 -->
    <transmission name="tran3">
        <type>transmission_interface/SimpleTransmission</type>
        <joint name="joint3">
            <hardwareInterface>hardware_interface/PositionJointInterface</hardwareInterface>
        </joint>
        <actuator name="motor3">
            <hardwareInterface>hardware_interface/PositionJointInterface</hardwareInterface>
            <mechanicalReduction>1</mechanicalReduction>
        </actuator>
    </transmission>
    <!-- Transmission 4 -->
    <transmission name="tran4">
        <type>transmission_interface/SimpleTransmission</type>
        <joint name="joint4">
            <hardwareInterface>hardware_interface/PositionJointInterface</hardwareInterface>
        </joint>
        <actuator name="motor4">
            <hardwareInterface>hardware_interface/PositionJointInterface</hardwareInterface>
            <mechanicalReduction>1</mechanicalReduction>
        </actuator>
    </transmission>
    <!-- Transmission 5 -->
    <transmission name="tran5">
        <type>transmission_interface/SimpleTransmission</type>
        <joint name="joint5">
            <hardwareInterface>hardware_interface/PositionJointInterface</hardwareInterface>
        </joint>
        <actuator name="motor5">
            <hardwareInterface>hardware_interface/PositionJointInterface</hardwareInterface>
            <mechanicalReduction>1</mechanicalReduction>
        </actuator>
    </transmission>
    <!-- Transmission 6 -->
    <transmission name="tran6">
        <type>transmission_interface/SimpleTransmission</type>
        <joint name="joint6">
            <hardwareInterface>hardware_interface/PositionJointInterface</hardwareInterface>
        </joint>
        <actuator name="motor6">
            <hardwareInterface>hardware_interface/PositionJointInterface</hardwareInterface>
            <mechanicalReduction>1</mechanicalReduction>
        </actuator>
    </transmission>
    <!-- Base -->
    <selfCollide>true</selfCollide>
    <gazebo reference="dsr01">
        <selfCollide>true</selfCollide>
        <plugin name="gazebo_ros_control">
            <robotNamespace>/</robotNamespace>
        </plugin>
    </gazebo>
    <gazebo reference="base_0">
        <selfCollide>true</selfCollide>
        <kp>1000000.0</kp>
        <kd>100.0</kd>
        <mu1>30.0</mu1>
        <mu2>30.0</mu2>
        <maxVel>1.0</maxVel>
        <minDepth>0.001</minDepth>
    </gazebo>
    <!-- Link1 -->
    <gazebo reference="link1">
        <selfCollide>true</selfCollide>
        <kp>1000000.0</kp>
        <kd>100.0</kd>
        <mu1>30.0</mu1>
        <mu2>30.0</mu2>
        <maxVel>1.0</maxVel>
        <minDepth>0.001</minDepth>
    </gazebo>
    <!-- Link2 -->
    <gazebo reference="link2">
        <selfCollide>true</selfCollide>
        <kp>1000000.0</kp>
        <kd>100.0</kd>
        <mu1>30.0</mu1>
        <mu2>30.0</mu2>
        <maxVel>1.0</maxVel>
        <minDepth>0.001</minDepth>
    </gazebo>
    <!-- Link3 -->
    <gazebo reference="link3">
        <selfCollide>true</selfCollide>
        <kp>1000000.0</kp>
        <kd>100.0</kd>
        <mu1>30.0</mu1>
        <mu2>30.0</mu2>
        <maxVel>1.0</maxVel>
        <minDepth>0.001</minDepth>
    </gazebo>
    <!-- Link4 -->
    <gazebo reference="link4">
        <selfCollide>true</selfCollide>
        <kp>1000000.0</kp>
        <kd>100.0</kd>
        <mu1>30.0</mu1>
        <mu2>30.0</mu2>
        <maxVel>1.0</maxVel>
        <minDepth>0.001</minDepth>
    </gazebo>
    <!-- Link5 -->
    <gazebo reference="link5">
        <selfCollide>true</selfCollide>
        <kp>1000000.0</kp>
        <kd>100.0</kd>
        <mu1>30.0</mu1>
        <mu2>30.0</mu2>
        <maxVel>1.0</maxVel>
        <minDepth>0.001</minDepth>
    </gazebo>
    <!-- Link6 -->
    <gazebo reference="link6">
        <selfCollide>true</selfCollide>
        <kp>1000000.0</kp>
        <kd>100.0</kd>
        <mu1>30.0</mu1>
        <mu2>30.0</mu2>
        <maxVel>1.0</maxVel>
        <minDepth>0.001</minDepth>
    </gazebo>
    <!-- ros_control plugin -->
    <gazebo>
        <selfCollide>true</selfCollide>
        <plugin filename="libgazebo_ros_control.so" name="gazebo_ros_control">
            <robotNamespace>/</robotNamespace>
            <controlPeriod>0.001</controlPeriod>
            <robotSimType>gazebo_ros_control/DefaultRobotHWSim</robotSimType>
            <legacyModeNS>true</legacyModeNS>
        </plugin>
    </gazebo>
    <link name="onrobot_rg2_base_link">
        <inertial>
            <origin rpy="0 0 0" xyz="0.0 0.0 0.0" />
            <mass value="0.7" />
            <inertia ixx="1.0E-03" ixy="1.0E-06" ixz="1.0E-06" iyy="1.0E-03" iyz="1.0E-06" izz="1.0E-03" />
        </inertial>
        <visual>
            <origin rpy="0 0 0" xyz="0 0 0" />
            <geometry>
                <mesh filename="package://onrobot_rg_description/meshes/rg2/visual/base_link.stl" />
            </geometry>
            <material name="">
                <color rgba="0.8 0.8 0.8 1" />
            </material>
        </visual>
        <collision>
            <origin rpy="0 0 0" xyz="0 0 0" />
            <geometry>
                <mesh filename="package://onrobot_rg_description/meshes/rg2/collision/base_link.stl" />
            </geometry>
        </collision>
    </link>
    <link name="world" />
    <joint name="joint0" type="fixed">
        <parent link="link6" />
        <child link="onrobot_rg2_base_link" />
        <origin rpy="0. 0. 0." xyz="0. 0. 0." />
    </joint>
    <gazebo reference="onrobot_rg2_base_link">
        <mu1>1.0</mu1>
        <mu2>1.0</mu2>
        <selfCollide>false</selfCollide>
        <material>Gazebo/White</material>
    </gazebo>
    <link name="left_outer_knuckle">
        <inertial>
            <origin rpy="0 0 0" xyz="0.0 0.0 0.0" />
            <mass value="0.05" />
            <inertia ixx="1.0E-03" ixy="1.0E-06" ixz="1.0E-06" iyy="1.0E-03" iyz="1.0E-06" izz="1.0E-03" />
        </inertial>
        <visual>
            <origin rpy="0 0 0" xyz="0 0 0" />
            <geometry>
                <mesh filename="package://onrobot_rg_description/meshes/rg2/visual/outer_knuckle.stl" />
            </geometry>
            <material name="">
                <color rgba="0.8 0.8 0.8 1" />
            </material>
        </visual>
        <collision>
            <origin rpy="0 0 0" xyz="0 0 0" />
            <geometry>
                <mesh filename="package://onrobot_rg_description/meshes/rg2/collision/outer_knuckle.stl" />
            </geometry>
        </collision>
    </link>
    <gazebo reference="left_outer_knuckle">
        <mu1>0.1</mu1>
        <mu2>0.1</mu2>
        <selfCollide>false</selfCollide>
        <material>Gazebo/White</material>
    </gazebo>
    <link name="left_inner_knuckle">
        <inertial>
            <origin rpy="0 0 0" xyz="0.0 0.0 0.0" />
            <mass value="0.05" />
            <inertia ixx="1.0E-03" ixy="1.0E-06" ixz="1.0E-06" iyy="1.0E-03" iyz="1.0E-06" izz="1.0E-03" />
        </inertial>
        <visual>
            <origin rpy="0 0 0" xyz="0 0 0" />
            <geometry>
                <mesh filename="package://onrobot_rg_description/meshes/rg2/visual/inner_knuckle.stl" />
            </geometry>
            <material name="">
                <color rgba="0.8 0.8 0.8 1" />
            </material>
        </visual>
        <collision>
            <origin rpy="0 0 0" xyz="0 0 0" />
            <geometry>
                <mesh filename="package://onrobot_rg_description/meshes/rg2/collision/inner_knuckle.stl" />
            </geometry>
        </collision>
    </link>
    <gazebo reference="left_inner_knuckle">
        <mu1>0.1</mu1>
        <mu2>0.1</mu2>
        <selfCollide>false</selfCollide>
        <material>Gazebo/White</material>
    </gazebo>
    <link name="left_inner_finger">
        <inertial>
            <origin rpy="0 0 0" xyz="0.0 0.0 0.0" />
            <mass value="0.05" />
            <inertia ixx="1.0E-03" ixy="1.0E-06" ixz="1.0E-06" iyy="1.0E-03" iyz="1.0E-06" izz="1.0E-03" />
        </inertial>
        <visual>
            <origin rpy="0 0 0" xyz="0 0 0" />
            <geometry>
                <mesh filename="package://onrobot_rg_description/meshes/rg2/visual/inner_finger.stl" />
            </geometry>
            <material name="">
                <color rgba="0.1 0.1 0.1 1" />
            </material>
        </visual>
        <collision>
            <origin rpy="0 0 0" xyz="0 0 0" />
            <geometry>
                <mesh filename="package://onrobot_rg_description/meshes/rg2/collision/inner_finger.stl" />
            </geometry>
        </collision>
    </link>
    <gazebo reference="left_inner_finger">
        <kp>1000000.0</kp>
        <kd>1.0</kd>
        <kd>1.0</kd>
        <mu1>1.0</mu1>
        <mu2>1.0</mu2>
        <minDepth>0.00001</minDepth>
        <selfCollide>false</selfCollide>
        <material>Gazebo/Black</material>
    </gazebo>
    <link name="right_outer_knuckle">
        <inertial>
            <origin rpy="0 0 0" xyz="0.0 0.0 0.0" />
            <mass value="0.05" />
            <inertia ixx="1.0E-03" ixy="1.0E-06" ixz="1.0E-06" iyy="1.0E-03" iyz="1.0E-06" izz="1.0E-03" />
        </inertial>
        <visual>
            <origin rpy="0 0 0" xyz="0 0 0" />
            <geometry>
                <mesh filename="package://onrobot_rg_description/meshes/rg2/visual/outer_knuckle.stl" />
            </geometry>
            <material name="">
                <color rgba="0.8 0.8 0.8 1" />
            </material>
        </visual>
        <collision>
            <origin rpy="0 0 0" xyz="0 0 0" />
            <geometry>
                <mesh filename="package://onrobot_rg_description/meshes/rg2/collision/outer_knuckle.stl" />
            </geometry>
        </collision>
    </link>
    <gazebo reference="right_outer_knuckle">
        <mu1>0.1</mu1>
        <mu2>0.1</mu2>
        <selfCollide>false</selfCollide>
        <material>Gazebo/White</material>
    </gazebo>
    <link name="right_inner_knuckle">
        <inertial>
            <origin rpy="0 0 0" xyz="0.0 0.0 0.0" />
            <mass value="0.05" />
            <inertia ixx="1.0E-03" ixy="1.0E-06" ixz="1.0E-06" iyy="1.0E-03" iyz="1.0E-06" izz="1.0E-03" />
        </inertial>
        <visual>
            <origin rpy="0 0 0" xyz="0 0 0" />
            <geometry>
                <mesh filename="package://onrobot_rg_description/meshes/rg2/visual/inner_knuckle.stl" />
            </geometry>
            <material name="">
                <color rgba="0.8 0.8 0.8 1" />
            </material>
        </visual>
        <collision>
            <origin rpy="0 0 0" xyz="0 0 0" />
            <geometry>
                <mesh filename="package://onrobot_rg_description/meshes/rg2/collision/inner_knuckle.stl" />
            </geometry>
        </collision>
    </link>
    <gazebo reference="right_inner_knuckle">
        <mu1>0.1</mu1>
        <mu2>0.1</mu2>
        <selfCollide>false</selfCollide>
        <material>Gazebo/White</material>
    </gazebo>
    <link name="right_inner_finger">
        <inertial>
            <origin rpy="0 0 0" xyz="0.0 0.0 0.0" />
            <mass value="0.05" />
            <inertia ixx="1.0E-03" ixy="1.0E-06" ixz="1.0E-06" iyy="1.0E-03" iyz="1.0E-06" izz="1.0E-03" />
        </inertial>
        <visual>
            <origin rpy="0 0 0" xyz="0 0 0" />
            <geometry>
                <mesh filename="package://onrobot_rg_description/meshes/rg2/visual/inner_finger.stl" />
            </geometry>
            <material name="">
                <color rgba="0.1 0.1 0.1 1" />
            </material>
        </visual>
        <collision>
            <origin rpy="0 0 0" xyz="0 0 0" />
            <geometry>
                <mesh filename="package://onrobot_rg_description/meshes/rg2/collision/inner_finger.stl" />
            </geometry>
        </collision>
    </link>
    <gazebo reference="right_inner_finger">
        <kp>1000000.0</kp>
        <kd>1.0</kd>
        <kd>1.0</kd>
        <mu1>1.0</mu1>
        <mu2>1.0</mu2>
        <minDepth>0.00001</minDepth>
        <selfCollide>false</selfCollide>
        <material>Gazebo/Black</material>
    </gazebo>
    <joint name="finger_joint" type="revolute">
        <origin rpy="0 0 0" xyz="0 -0.017178 0.125797" />
        <parent link="onrobot_rg2_base_link" />
        <child link="left_outer_knuckle" />
        <axis xyz="-1 0 0" />
        <limit effort="1000" lower="-0.558505" upper="0.785398" velocity="100.0" />
    </joint>
    <joint name="left_inner_knuckle_joint" type="revolute">
        <origin rpy="0 0 0.0" xyz="0 -0.007678 0.1422970" />
        <parent link="onrobot_rg2_base_link" />
        <child link="left_inner_knuckle" />
        <axis xyz="1 0 0" />
        <limit effort="1000" lower="-0.785398" upper="0.785398" velocity="100.0" />
        <mimic joint="finger_joint" multiplier="-1" offset="0" />
    </joint>
    <joint name="left_inner_finger_joint" type="revolute">
        <origin rpy="0 0 0" xyz="0 -0.039592 0.038177000000000016" />
        <parent link="left_outer_knuckle" />
        <child link="left_inner_finger" />
        <axis xyz="1 0 0" />
        <limit effort="1000" lower="-0.872665" upper="0.872665" velocity="100.0" />
        <mimic joint="finger_joint" multiplier="1" offset="0" />
    </joint>
    <joint name="right_outer_knuckle_joint" type="revolute">
        <origin rpy="0 0 3.141592653589793" xyz="0 0.017178 0.125797" />
        <parent link="onrobot_rg2_base_link" />
        <child link="right_outer_knuckle" />
        <axis xyz="1 0 0" />
        <limit effort="1000" lower="-0.785398" upper="0.785398" velocity="100.0" />
        <mimic joint="finger_joint" multiplier="-1" offset="0" />
    </joint>
    <joint name="right_inner_knuckle_joint" type="revolute">
        <origin rpy="0 0 -3.141592653589793" xyz="0 0.007678 0.1422970" />
        <parent link="onrobot_rg2_base_link" />
        <child link="right_inner_knuckle" />
        <axis xyz="1 0 0" />
        <limit effort="1000" lower="-0.785398" upper="0.785398" velocity="100.0" />
        <mimic joint="finger_joint" multiplier="-1" offset="0" />
    </joint>
    <joint name="right_inner_finger_joint" type="revolute">
        <origin rpy="0 0 0" xyz="0 -0.039592 0.038177000000000016" />
        <parent link="right_outer_knuckle" />
        <child link="right_inner_finger" />
        <axis xyz="1 0 0" />
        <limit effort="1000" lower="-0.872665" upper="0.872665" velocity="100.0" />
        <mimic joint="finger_joint" multiplier="1" offset="0" />
    </joint>
    <transmission name="finger_joint_trans">
        <type>transmission_interface/SimpleTransmission</type>
        <joint name="finger_joint">
            <hardwareInterface>hardware_interface/EffortJointInterface</hardwareInterface>
        </joint>
        <actuator name="finger_joint_motor">
            <hardwareInterface>hardware_interface/EffortJointInterface</hardwareInterface>
            <mechanicalReduction>1</mechanicalReduction>
        </actuator>
    </transmission>
    <gazebo>
        <plugin filename="libroboticsgroup_upatras_gazebo_mimic_joint_plugin.so" name="mimic_left_inner_knuckle_joint">
            <joint>finger_joint</joint>
            <mimicJoint>left_inner_knuckle_joint</mimicJoint>
            <multiplier>-1.0</multiplier>
            <offset>0.0</offset>
            <maxEffort>5.0</maxEffort>
            <!-- <hasPID /> -->
        </plugin>
        <plugin filename="libroboticsgroup_upatras_gazebo_mimic_joint_plugin.so" name="mimic_right_inner_knuckle_joint">
            <joint>finger_joint</joint>
            <mimicJoint>right_inner_knuckle_joint</mimicJoint>
            <multiplier>-1.0</multiplier>
            <offset>0.0</offset>
            <maxEffort>5.0</maxEffort>
            <!-- <hasPID /> -->
        </plugin>
        <plugin filename="libroboticsgroup_upatras_gazebo_mimic_joint_plugin.so" name="mimic_left_inner_finger_joint">
            <joint>finger_joint</joint>
            <mimicJoint>left_inner_finger_joint</mimicJoint>
            <multiplier>1.0</multiplier>
            <offset>0.0</offset>
            <maxEffort>5.0</maxEffort>
            <!-- <hasPID /> -->
        </plugin>
        <plugin filename="libroboticsgroup_upatras_gazebo_mimic_joint_plugin.so" name="mimic_right_inner_finger_joint">
            <joint>finger_joint</joint>
            <mimicJoint>right_inner_finger_joint</mimicJoint>
            <multiplier>1.0</multiplier>
            <offset>0.0</offset>
            <maxEffort>5.0</maxEffort>
            <!-- <hasPID /> -->
        </plugin>
        <plugin filename="libroboticsgroup_upatras_gazebo_mimic_joint_plugin.so" name="mimic_right_outer_knuckle_joint">
            <joint>finger_joint</joint>
            <mimicJoint>right_outer_knuckle_joint</mimicJoint>
            <multiplier>-1.0</multiplier>
            <offset>0.0</offset>
            <maxEffort>5.0</maxEffort>
            <!-- <hasPID /> -->
        </plugin>
    </gazebo>
    <!-- material -->
    <material name="red">
        <color rgba="0.8 0.0 0.0 1" />
    </material>
    <!-- Camera -->
    <link name="camera_link">
        <collision>
            <origin rpy="0 0 0" xyz="0 0 0" />
            <geometry>
                <box size="0.05 0.05 0.05" />
            </geometry>
        </collision>
        <visual>
            <origin rpy="0 0 0" xyz="0 0 0" />
            <geometry>
                <box size="0.010 0.03 0.03" />
            </geometry>
            <material name="red" />
        </visual>
        <inertial>
            <mass value="1e-5" />
            <origin rpy="0 0 0" xyz="0 0 0" />
            <inertia ixx="1e-6" ixy="0" ixz="0" iyy="1e-6" iyz="0" izz="1e-6" />
        </inertial>
    </link>
    <joint name="camera_joint" type="fixed">
        <parent link="link6" />
        <child link="camera_link" />
        <origin rpy="0 -1.57 3.14" xyz="0.03 0 0.12" />
    </joint>
    <gazebo reference="camera_link">
        <sensor name="camera1" type="camera">
            <visualize>true</visualize>
            <update_rate>30.0</update_rate>
            <camera name="head">
                <horizontal_fov>1.3962634</horizontal_fov>
                <image>
                    <width>800</width>
                    <height>800</height>
                    <format>R8G8B8</format>
                </image>
                <clip>
                    <near>0.02</near>
                    <far>300</far>
                </clip>
                <noise>
                    <type>gaussian</type>
                    <!-- Noise is sampled independently per pixel on each frame.
                  That pixel's noise value is added to each of its color
                  channels, which at that point lie in the range [0,1]. -->
                    <mean>0.0</mean>
                    <stddev>0.007</stddev>
                </noise>
            </camera>
            <plugin filename="libgazebo_ros_camera.so" name="camera_controller">
                <alwaysOn>true</alwaysOn>
                <updateRate>0.0</updateRate>
                <cameraName>robotic_arm/camera1</cameraName>
                <imageTopicName>image_raw</imageTopicName>
                <cameraInfoTopicName>camera_info</cameraInfoTopicName>
                <frameName>camera_link</frameName>
                <hackBaseline>0.07</hackBaseline>
                <distortionK1>0.0</distortionK1>
                <distortionK2>0.0</distortionK2>
                <distortionK3>0.0</distortionK3>
                <distortionT1>0.0</distortionT1>
                <distortionT2>0.0</distortionT2>
            </plugin>
        </sensor>
    </gazebo>
    <!-- World fixed joint-->
    <joint name="world_fixed" type="fixed">
        <origin rpy="0 0 0" xyz="0 0 0" />
        <parent link="world" />
        <child link="base_0" />
    </joint>
    <transmission name="trans_left_inner_knuckle_joint">
        <type>transmission_interface/SimpleTransmission</type>
        <joint name="left_inner_knuckle_joint">
            <hardwareInterface>hardware_interface/EffortJointInterface</hardwareInterface>
        </joint>
        <actuator name="left_inner_knuckle_joint_motor">
            <hardwareInterface>hardware_interface/EffortJointInterface</hardwareInterface>
            <mechanicalReduction>1</mechanicalReduction>
        </actuator>
    </transmission>
    <transmission name="trans_left_inner_finger_joint">
        <type>transmission_interface/SimpleTransmission</type>
        <joint name="left_inner_finger_joint">
            <hardwareInterface>hardware_interface/EffortJointInterface</hardwareInterface>
        </joint>
        <actuator name="left_inner_finger_joint_motor">
            <hardwareInterface>hardware_interface/EffortJointInterface</hardwareInterface>
            <mechanicalReduction>1</mechanicalReduction>
        </actuator>
    </transmission>
    <transmission name="trans_right_outer_knuckle_joint">
        <type>transmission_interface/SimpleTransmission</type>
        <joint name="right_outer_knuckle_joint">
            <hardwareInterface>hardware_interface/EffortJointInterface</hardwareInterface>
        </joint>
        <actuator name="right_outer_knuckle_joint_motor">
            <hardwareInterface>hardware_interface/EffortJointInterface</hardwareInterface>
            <mechanicalReduction>1</mechanicalReduction>
        </actuator>
    </transmission>
    <transmission name="trans_right_inner_knuckle_joint">
        <type>transmission_interface/SimpleTransmission</type>
        <joint name="right_inner_knuckle_joint">
            <hardwareInterface>hardware_interface/EffortJointInterface</hardwareInterface>
        </joint>
        <actuator name="right_inner_knuckle_joint_motor">
            <hardwareInterface>hardware_interface/EffortJointInterface</hardwareInterface>
            <mechanicalReduction>1</mechanicalReduction>
        </actuator>
    </transmission>
    <transmission name="trans_right_inner_finger_joint">
        <type>transmission_interface/SimpleTransmission</type>
        <joint name="right_inner_finger_joint">
            <hardwareInterface>hardware_interface/EffortJointInterface</hardwareInterface>
        </joint>
        <actuator name="right_inner_finger_joint_motor">
            <hardwareInterface>hardware_interface/EffortJointInterface</hardwareInterface>
            <mechanicalReduction>1</mechanicalReduction>
        </actuator>
    </transmission>
</robot>

